Workbook

Sheet הוראות שימוש
B2: מחשבון ציון CAIQ לספקי SaaS
B3: Cloud Security Alliance · Cloud Controls Matrix v4 · 17 דומיינים
B5: 📋 מהו הכלי הזה?
B6: כלי זה מאפשר לכם לחשב ציון סיכון מובנה לספק SaaS על בסיס שאלון CAIQ (Consensus Assessments Initiative Questionnaire) של ה-Cloud Security Alliance.
B8: 📄 גיליונות בחוברת:
B9: שאלון CAIQ | C9: הזינו תשובות כן/לא/לא רלוונטי לכל 261 השאלות. לחצו על הרשימה הנגללת בכל תא.
B10: ציון לפי דומיין | C10: סיכום אוטומטי של הציון לכל אחד מ-17 הדומיינים עם משקלות.
B11: ציון כולל | C11: לוח מחוונים מסכם עם דירוג הסיכון הסופי והמלצות.
B13: ⚙️ הוראות:
B14: שלב 1 | C14: עברו לגיליון 'שאלון CAIQ' והזינו תשובות לכל שאלה.
B15: שלב 2 | C15: ניתן לשנות משקלות ב'ציון לפי דומיין' בעמודת המשקל.
B16: שלב 3 | C16: הציון הכולל מחושב אוטומטית — ראו 'ציון כולל'.
B18: 🔴 בקרות חסמות:
B19: בקרות מסוימות הן חסמות — תשובה 'לא' גוררת סימון אדום. בדקו את עמודת 'חסמת' בשאלון.
B21: 🟢 דירוג סיכון:
B22: 85–100% | C22: 🟢 סיכון נמוך — אישור מלא
B23: 70–84% | C23: 🟡 סיכון בינוני — אישור עם מעקב
B24: 50–69% | C24: 🟠 סיכון גבוה — דרוש שיפור
B25: מתחת ל-50% | C25: 🔴 סיכון קריטי — לא מאושר

Sheet שאלון CAIQ
A1: מזהה בקרה | B1: שאלת CAIQ | C1: דומיין | D1: חסמת? | E1: תשובה (כן/לא/לא רלוונטי) | F1: הערות
A2: 📁 Application & Interface Security
A3: AIS-01.1 | B3: האם ישנה מדיניות אפליקציות ותוכנה מוגדרת? | C3: Application & Interface Security
A4: AIS-01.2 | B4: האם המדיניות מתועדת ומיושמת? | C4: Application & Interface Security
A5: AIS-02.1 | B5: האם נעשה שימוש בגישת Security by Design? | C5: Application & Interface Security | D5: ✓
A6: AIS-02.2 | B6: האם קיים תהליך בדיקת אבטחה לפני השקת תכונות? | C6: Application & Interface Security | D6: ✓
A7: AIS-03.1 | B7: האם קיים תהליך Secure SDLC? | C7: Application & Interface Security | D7: ✓
A8: AIS-04.1 | B8: האם מתבצעות בדיקות אבטחה אוטומטיות (SAST/DAST)? | C8: Application & Interface Security
A9: AIS-04.2 | B9: האם קיים תהליך Code Review לאבטחה? | C9: Application & Interface Security
A10: AIS-05.1 | B10: האם ישנה בדיקת תלויות ורכיבי צד שלישי (SCA)? | C10: Application & Interface Security
A11: AIS-06.1 | B11: האם קיים API Gateway עם הגבלות גישה? | C11: Application & Interface Security
A12: AIS-06.2 | B12: האם ממשקי API מוגנים מפני שימוש לרעה? | C12: Application & Interface Security | D12: ✓
A13: 📁 Business Continuity & Resilience
A14: BCR-01.1 | B14: האם קיים תוכנית המשכיות עסקית (BCP)? | C14: Business Continuity & Resilience | D14: ✓
A15: BCR-01.2 | B15: האם התוכנית נבדקה ב-12 החודשים האחרונים? | C15: Business Continuity & Resilience
A16: BCR-02.1 | B16: האם קיים תוכנית התאוששות מאסון (DRP)? | C16: Business Continuity & Resilience | D16: ✓
A17: BCR-02.2 | B17: האם ה-DRP נבדק ב-12 החודשים האחרונים? | C17: Business Continuity & Resilience
A18: BCR-03.1 | B18: האם RTO מוגדר וידוע? | C18: Business Continuity & Resilience
A19: BCR-03.2 | B19: האם RPO מוגדר וידוע? | C19: Business Continuity & Resilience
A20: BCR-04.1 | B20: האם גיבויים מתבצעים לפחות יומיים? | C20: Business Continuity & Resilience | D20: ✓
A21: BCR-04.2 | B21: האם גיבויים נשמרים באתר גיאוגרפי שני? | C21: Business Continuity & Resilience
A22: BCR-05.1 | B22: האם קיימת יתירות (Redundancy) לתשתית? | C22: Business Continuity & Resilience
A23: BCR-05.2 | B23: האם תשתיות קריטיות כפולות? | C23: Business Continuity & Resilience
A24: BCR-06.1 | B24: האם SLA זמינות הוא 99.9% או יותר? | C24: Business Continuity & Resilience
A25: BCR-11.1 | B25: האם מתבצעות תרגילי Failover תקופתיים? | C25: Business Continuity & Resilience
A26: 📁 Change Control & Configuration
A27: CCC-01.1 | B27: האם קיים תהליך ניהול שינויים? | C27: Change Control & Configuration
A28: CCC-02.1 | B28: האם כל שינוי מאושר לפני יישום? | C28: Change Control & Configuration | D28: ✓
A29: CCC-03.1 | B29: האם קיים CI/CD Pipeline? | C29: Change Control & Configuration
A30: CCC-04.1 | B30: האם קיים ניהול תצורה (Configuration Management)? | C30: Change Control & Configuration
A31: CCC-05.1 | B31: האם שינויים במוצר נבדקים בסביבת TEST לפני PROD? | C31: Change Control & Configuration | D31: ✓
A32: CCC-06.1 | B32: האם קיים Rollback לשינויים כושלים? | C32: Change Control & Configuration
A33: CCC-07.1 | B33: האם שינויים מתועדים ומוצגים ללקוחות? | C33: Change Control & Configuration
A34: 📁 Cryptography & Key Management
A35: CEK-01.1 | B35: האם קיימת מדיניות הצפנה מתועדת? | C35: Cryptography & Key Management | D35: ✓
A36: CEK-02.1 | B36: האם נתונים מוצפנים במנוחה (at rest)? | C36: Cryptography & Key Management | D36: ✓
A37: CEK-02.2 | B37: האם אלגוריתם ההצפנה הוא AES-256 או שווה? | C37: Cryptography & Key Management | D37: ✓
A38: CEK-03.1 | B38: האם נתונים מוצפנים במעבר (in transit) עם TLS 1.2+? | C38: Cryptography & Key Management | D38: ✓
A39: CEK-04.1 | B39: האם קיים ניהול מפתחות הצפנה (KMS)? | C39: Cryptography & Key Management
A40: CEK-04.2 | B40: האם מפתחות מוחלפים תקופתית? | C40: Cryptography & Key Management
...

Sheet ציון לפי דומיין
A1: ציון CAIQ לפי דומיין
A2: קוד | B2: שם הדומיין | C2: משקל % | D2: תשובות כן | E2: תשובות לא | F2: שאלות רלוונטיות | G2: ציון דומיין % | H2: ציון משוקלל %
A3: AIS | B3: Application & Interface Security | C3: 6 | D3: =COUNTIF('שאלון CAIQ'!E3:E12,"כן") -> 0 | E3: =COUNTIF('שאלון CAIQ'!E3:E12,"לא") -> 0 | F3: =COUNTA('שאלון CAIQ'!E3:E12)-COUNTIF('שאלון CAIQ'!E3:E12,"לא רלוונטי") -> 0 | G3: =IF(F3=0,0,D3/F3) -> 0 | H3: =G3*C3/100 -> 0
A4: BCR | B4: Business Continuity & Resilience | C4: 7 | D4: =COUNTIF('שאלון CAIQ'!E14:E25,"כן") -> 0 | E4: =COUNTIF('שאלון CAIQ'!E14:E25,"לא") -> 0 | F4: =COUNTA('שאלון CAIQ'!E14:E25)-COUNTIF('שאלון CAIQ'!E14:E25,"לא רלוונטי") -> 0 | G4: =IF(F4=0,0,D4/F4) -> 0 | H4: =G4*C4/100 -> 0
A5: CCC | B5: Change Control & Configuration | C5: 5 | D5: =COUNTIF('שאלון CAIQ'!E27:E33,"כן") -> 0 | E5: =COUNTIF('שאלון CAIQ'!E27:E33,"לא") -> 0 | F5: =COUNTA('שאלון CAIQ'!E27:E33)-COUNTIF('שאלון CAIQ'!E27:E33,"לא רלוונטי") -> 0 | G5: =IF(F5=0,0,D5/F5) -> 0 | H5: =G5*C5/100 -> 0
A6: CEK | B6: Cryptography & Key Management | C6: 8 | D6: =COUNTIF('שאלון CAIQ'!E35:E42,"כן") -> 0 | E6: =COUNTIF('שאלון CAIQ'!E35:E42,"לא") -> 0 | F6: =COUNTA('שאלון CAIQ'!E35:E42)-COUNTIF('שאלון CAIQ'!E35:E42,"לא רלוונטי") -> 0 | G6: =IF(F6=0,0,D6/F6) -> 0 | H6: =G6*C6/100 -> 0
A7: DCS | B7: Datacenter Security | C7: 5 | D7: =COUNTIF('שאלון CAIQ'!E44:E49,"כן") -> 0 | E7: =COUNTIF('שאלון CAIQ'!E44:E49,"לא") -> 0 | F7: =COUNTA('שאלון CAIQ'!E44:E49)-COUNTIF('שאלון CAIQ'!E44:E49,"לא רלוונטי") -> 0 | G7: =IF(F7=0,0,D7/F7) -> 0 | H7: =G7*C7/100 -> 0
A8: DSP | B8: Data Security & Privacy | C8: 10 | D8: =COUNTIF('שאלון CAIQ'!E51:E62,"כן") -> 0 | E8: =COUNTIF('שאלון CAIQ'!E51:E62,"לא") -> 0 | F8: =COUNTA('שאלון CAIQ'!E51:E62)-COUNTIF('שאלון CAIQ'!E51:E62,"לא רלוונטי") -> 0 | G8: =IF(F8=0,0,D8/F8) -> 0 | H8: =G8*C8/100 -> 0
A9: GRC | B9: Governance, Risk & Compliance | C9: 5 | D9: =COUNTIF('שאלון CAIQ'!E64:E69,"כן") -> 0 | E9: =COUNTIF('שאלון CAIQ'!E64:E69,"לא") -> 0 | F9: =COUNTA('שאלון CAIQ'!E64:E69)-COUNTIF('שאלון CAIQ'!E64:E69,"לא רלוונטי") -> 0 | G9: =IF(F9=0,0,D9/F9) -> 0 | H9: =G9*C9/100 -> 0
A10: HRS | B10: Human Resources | C10: 4 | D10: =COUNTIF('שאלון CAIQ'!E71:E76,"כן") -> 0 | E10: =COUNTIF('שאלון CAIQ'!E71:E76,"לא") -> 0 | F10: =COUNTA('שאלון CAIQ'!E71:E76)-COUNTIF('שאלון CAIQ'!E71:E76,"לא רלוונטי") -> 0 | G10: =IF(F10=0,0,D10/F10) -> 0 | H10: =G10*C10/100 -> 0
A11: IAM | B11: Identity & Access Management | C11: 12 | D11: =COUNTIF('שאלון CAIQ'!E78:E89,"כן") -> 0 | E11: =COUNTIF('שאלון CAIQ'!E78:E89,"לא") -> 0 | F11: =COUNTA('שאלון CAIQ'!E78:E89)-COUNTIF('שאלון CAIQ'!E78:E89,"לא רלוונטי") -> 0 | G11: =IF(F11=0,0,D11/F11) -> 0 | H11: =G11*C11/100 -> 0
A12: IPY | B12: Interoperability & Portability | C12: 3 | D12: =COUNTIF('שאלון CAIQ'!E91:E94,"כן") -> 0 | E12: =COUNTIF('שאלון CAIQ'!E91:E94,"לא") -> 0 | F12: =COUNTA('שאלון CAIQ'!E91:E94)-COUNTIF('שאלון CAIQ'!E91:E94,"לא רלוונטי") -> 0 | G12: =IF(F12=0,0,D12/F12) -> 0 | H12: =G12*C12/100 -> 0
A13: IVS | B13: Infrastructure & Virtualization | C13: 7 | D13: =COUNTIF('שאלון CAIQ'!E96:E102,"כן") -> 0 | E13: =COUNTIF('שאלון CAIQ'!E96:E102,"לא") -> 0 | F13: =COUNTA('שאלון CAIQ'!E96:E102)-COUNTIF('שאלון CAIQ'!E96:E102,"לא רלוונטי") -> 0 | G13: =IF(F13=0,0,D13/F13) -> 0 | H13: =G13*C13/100 -> 0
A14: LOG | B14: Logging & Monitoring | C14: 6 | D14: =COUNTIF('שאלון CAIQ'!E104:E110,"כן") -> 0 | E14: =COUNTIF('שאלון CAIQ'!E104:E110,"לא") -> 0 | F14: =COUNTA('שאלון CAIQ'!E104:E110)-COUNTIF('שאלון CAIQ'!E104:E110,"לא רלוונטי") -> 0 | G14: =IF(F14=0,0,D14/F14) -> 0 | H14: =G14*C14/100 -> 0
A15: SEF | B15: Security Incident Management | C15: 8 | D15: =COUNTIF('שאלון CAIQ'!E112:E119,"כן") -> 0 | E15: =COUNTIF('שאלון CAIQ'!E112:E119,"לא") -> 0 | F15: =COUNTA('שאלון CAIQ'!E112:E119)-COUNTIF('שאלון CAIQ'!E112:E119,"לא רלוונטי") -> 0 | G15: =IF(F15=0,0,D15/F15) -> 0 | H15: =G15*C15/100 -> 0
A16: STA | B16: Supply Chain Management | C16: 6 | D16: =COUNTIF('שאלון CAIQ'!E121:E126,"כן") -> 0 | E16: =COUNTIF('שאלון CAIQ'!E121:E126,"לא") -> 0 | F16: =COUNTA('שאלון CAIQ'!E121:E126)-COUNTIF('שאלון CAIQ'!E121:E126,"לא רלוונטי") -> 0 | G16: =IF(F16=0,0,D16/F16) -> 0 | H16: =G16*C16/100 -> 0
A17: TVM | B17: Threat & Vulnerability Mgmt | C17: 7 | D17: =COUNTIF('שאלון CAIQ'!E128:E134,"כן") -> 0 | E17: =COUNTIF('שאלון CAIQ'!E128:E134,"לא") -> 0 | F17: =COUNTA('שאלון CAIQ'!E128:E134)-COUNTIF('שאלון CAIQ'!E128:E134,"לא רלוונטי") -> 0 | G17: =IF(F17=0,0,D17/F17) -> 0 | H17: =G17*C17/100 -> 0
A18: UEM | B18: Endpoint Management | C18: 4 | D18: =COUNTIF('שאלון CAIQ'!E136:E139,"כן") -> 0 | E18: =COUNTIF('שאלון CAIQ'!E136:E139,"לא") -> 0 | F18: =COUNTA('שאלון CAIQ'!E136:E139)-COUNTIF('שאלון CAIQ'!E136:E139,"לא רלוונטי") -> 0 | G18: =IF(F18=0,0,D18/F18) -> 0 | H18: =G18*C18/100 -> 0
A19: HRS2 | B19: Audit Assurance & Compliance | C19: 7 | D19: =COUNTIF('שאלון CAIQ'!E141:E147,"כן") -> 0 | E19: =COUNTIF('שאלון CAIQ'!E141:E147,"לא") -> 0 | F19: =COUNTA('שאלון CAIQ'!E141:E147)-COUNTIF('שאלון CAIQ'!E141:E147,"לא רלוונטי") -> 0 | G19: =IF(F19=0,0,D19/F19) -> 0 | H19: =G19*C19/100 -> 0
A20: סה"כ | C20: =SUM(C3:C19) -> 110 | D20: =SUM(D3:D19) -> 0 | E20: =SUM(E3:E19) -> 0 | F20: =SUM(F3:F19) -> 0 | G20: =IF(F20=0,0,D20/F20) -> 0 | H20: =SUM(H3:H19) -> 0

Sheet ציון כולל
B2: דו"ח ציון CAIQ – סיכום מנהלים
B3: Cloud Security Alliance · Consensus Assessments Initiative Questionnaire v4
B5: שם הספק: | D5: תאריך הערכה:
B6: מעריך: | D6: גרסת CAIQ: | E6: CAIQ v4.0
B8: ציון אבטחה כולל
B9: ='ציון לפי דומיין'!H20*100 -> 0
B10: =IF(B9>=85,"🟢 סיכון נמוך – אישור מלא",IF(B9>=70,"🟡 סיכון בינוני – אישור עם מעקב",IF(B9>=50,"🟠 סיכון גבוה – דרוש שיפור","🔴 סיכון קריטי – לא מאושר"))) -> 🔴 סיכון קריטי – לא מאושר
B13: ✅ תשובות כן | C13: ❌ תשובות לא | D13: ⬜ שאלות רלוונטיות | E13: 📊 כיסוי שאלות
B14: ='ציון לפי דומיין'!D20 -> 0 | C14: ='ציון לפי דומיין'!E20 -> 0 | D14: ='ציון לפי דומיין'!F20 -> 0 | E14: ='ציון לפי דומיין'!F20/261 -> 0
B17: פירוט ציון לפי דומיין
B18: דומיין | C18: ציון % | D18: משקל | E18: ציון משוקלל
B19: ='ציון לפי דומיין'!B3 -> Application & Interface Security | C19: ='ציון לפי דומיין'!G3 -> 0 | D19: ='ציון לפי דומיין'!C3/100 -> 0.06 | E19: ='ציון לפי דומיין'!H3 -> 0
B20: ='ציון לפי דומיין'!B4 -> Business Continuity & Resilience | C20: ='ציון לפי דומיין'!G4 -> 0 | D20: ='ציון לפי דומיין'!C4/100 -> 0.07 | E20: ='ציון לפי דומיין'!H4 -> 0
B21: ='ציון לפי דומיין'!B5 -> Change Control & Configuration | C21: ='ציון לפי דומיין'!G5 -> 0 | D21: ='ציון לפי דומיין'!C5/100 -> 0.05 | E21: ='ציון לפי דומיין'!H5 -> 0
B22: ='ציון לפי דומיין'!B6 -> Cryptography & Key Management | C22: ='ציון לפי דומיין'!G6 -> 0 | D22: ='ציון לפי דומיין'!C6/100 -> 0.08 | E22: ='ציון לפי דומיין'!H6 -> 0
B23: ='ציון לפי דומיין'!B7 -> Datacenter Security | C23: ='ציון לפי דומיין'!G7 -> 0 | D23: ='ציון לפי דומיין'!C7/100 -> 0.05 | E23: ='ציון לפי דומיין'!H7 -> 0
B24: ='ציון לפי דומיין'!B8 -> Data Security & Privacy | C24: ='ציון לפי דומיין'!G8 -> 0 | D24: ='ציון לפי דומיין'!C8/100 -> 0.1 | E24: ='ציון לפי דומיין'!H8 -> 0
B25: ='ציון לפי דומיין'!B9 -> Governance, Risk & Compliance | C25: ='ציון לפי דומיין'!G9 -> 0 | D25: ='ציון לפי דומיין'!C9/100 -> 0.05 | E25: ='ציון לפי דומיין'!H9 -> 0
B26: ='ציון לפי דומיין'!B10 -> Human Resources | C26: ='ציון לפי דומיין'!G10 -> 0 | D26: ='ציון לפי דומיין'!C10/100 -> 0.04 | E26: ='ציון לפי דומיין'!H10 -> 0
B27: ='ציון לפי דומיין'!B11 -> Identity & Access Management | C27: ='ציון לפי דומיין'!G11 -> 0 | D27: ='ציון לפי דומיין'!C11/100 -> 0.12 | E27: ='ציון לפי דומיין'!H11 -> 0
B28: ='ציון לפי דומיין'!B12 -> Interoperability & Portability | C28: ='ציון לפי דומיין'!G12 -> 0 | D28: ='ציון לפי דומיין'!C12/100 -> 0.03 | E28: ='ציון לפי דומיין'!H12 -> 0
B29: ='ציון לפי דומיין'!B13 -> Infrastructure & Virtualization | C29: ='ציון לפי דומיין'!G13 -> 0 | D29: ='ציון לפי דומיין'!C13/100 -> 0.07 | E29: ='ציון לפי דומיין'!H13 -> 0
B30: ='ציון לפי דומיין'!B14 -> Logging & Monitoring | C30: ='ציון לפי דומיין'!G14 -> 0 | D30: ='ציון לפי דומיין'!C14/100 -> 0.06 | E30: ='ציון לפי דומיין'!H14 -> 0
... B35: ='ציון לפי דומיין'!B19 -> Audit Assurance & Compliance | C35: ='ציון לפי דומיין'!G19 -> 0 | D35: ='ציון לפי דומיין'!C19/100 -> 0.07 | E35: ='ציון לפי דומיין'!H19 -> 0
